<?xml version="1.0" ?>
<!-- =================================================================================== -->
<!-- |    This document was autogenerated by xacro from my_leg.xacro                   | -->
<!-- |    EDITING THIS FILE BY HAND IS NOT RECOMMENDED                                 | -->
<!-- =================================================================================== -->
<robot name="RR">
  <!-- Colors -->
  <material name="blue">
    <color rgba="0 0 0.8 1"/>
  </material>
  <material name="red">
    <color rgba="0.8 0 0 1"/>
  </material>
  <material name="grey">
    <color rgba="0.5 0.5 0.5 1"/>
  </material>
  <material name="DarkGrey">
    <color rgba="0.3 0.3 0.3 1"/>
  </material>
  <!-- Addin objects: -->
  <link name="world"/>
  <!-- Base Link  -->
  <link name="base_link">
    <visual>
      <geometry>
        <mesh filename="package://leg_description/meshes/Base.STL" scale=".001 .001 .001"/>
      </geometry>
      <origin rpy="0 0 0" xyz="0 0 0"/>
      <material name="DarkGrey"/>
    </visual>
    <collision>
      <geometry>
        <cylinder length="0.05708" radius="0.05555"/>
      </geometry>
      <origin rpy="0 0 0" xyz="0 0 0.00656"/>
    </collision>
    <inertial>
      <mass value="0.4759"/>
      <inertia ixx="0.000576572" ixy="1.091449e-05" ixz="-4.096e-06" iyy="0.000825053" iyz="-3.018e-06" izz="0.000391889"/>
      <origin rpy="0 0 0" xyz="-0.00083 -0.00061 0.01032"/>
    </inertial>
  </link>
  <joint name="world_joint" type="fixed">
    <parent link="world"/>
    <child link="base_link"/>
    <origin rpy="1.5707963267948966 -1.5707963267948966 0" xyz="0.05555 0 0.4"/>
  </joint>
  <!-- Link 1  -->
  <link name="link1">
    <visual>
      <geometry>
        <mesh filename="package://leg_description/meshes/link1.STL" scale=".001 .001 .001"/>
      </geometry>
      <origin rpy="0 0 0" xyz="0 0 0"/>
      <material name="grey"/>
    </visual>
    <collision>
      <geometry>
        <cylinder length="0.12457999999999998" radius="0.05555"/>
      </geometry>
      <origin rpy="1.5707963267948966 0 0" xyz="0  -0.027289999999999988 0"/>
    </collision>
    <inertial>
      <mass value="0.4759"/>
      <inertia ixx="0.000576572" ixy="1.091449e-05" ixz="-4.096e-06" iyy="0.000825053" iyz="-3.018e-06" izz="0.000391889"/>
      <origin rpy="0 0 0" xyz="-0.00083 -0.00061 0.01032"/>
    </inertial>
  </link>
  <joint name="base_to_link1" type="revolute">
    <parent link="base_link"/>
    <child link="link1"/>
    <axis rpy="0 0 0" xyz="0 0 1"/>
    <limit effort="7.051407999999999" lower="-1.5707963267948966" upper="1.5707963267948966" velocity="55.48571428571428"/>
    <origin rpy="0 0 0" xyz="0 0 -0.07763"/>
  </joint>
  <transmission name="base_link1_trans">
    <type>transmission_interface/SimpleTransmission</type>
    <actuator name="motor1">
      <mechanicalReduction>7</mechanicalReduction>
    </actuator>
    <joint name="base_to_link1">
      <hardwareInterface>hardware_interface/EffortJointInterface</hardwareInterface>
    </joint>
  </transmission>
  <!-- Link 2  -->
  <link name="link2">
    <visual>
      <geometry>
        <mesh filename="package://leg_description/meshes/link2.STL" scale=".001 .001 .001"/>
      </geometry>
      <origin rpy="0 0 0" xyz="0 0 0"/>
      <material name="DarkGrey"/>
    </visual>
    <collision name="link2_leg">
      <geometry>
        <cylinder length="0.2531" radius="0.0205"/>
      </geometry>
      <origin rpy="0 1.5707963267948966 0" xyz="0.12655 0 0"/>
    </collision>
    <collision name="link2_hip">
      <geometry>
        <box size="0.128 0.07 0.045"/>
      </geometry>
      <origin rpy="0 0 0" xyz="0.028 0 0"/>
    </collision>
    <inertial>
      <mass value="0.94987"/>
      <inertia ixx="0.001561735" ixy="-1.2537e-05" ixz="-0.000843757" iyy="0.005174717" iyz="-1.72e-05" izz="0.004776989"/>
      <origin rpy="0 0 0" xyz="0.03158 -0.00042 -0.02813"/>
    </inertial>
  </link>
  <joint name="link1_to_link2" type="continuous">
    <parent link="link1"/>
    <child link="link2"/>
    <axis rpy="0 0 0" xyz="0 0 1"/>
    <origin rpy="1.5707963267948966 1.5707963267948966 0" xyz="0 -0.11208  0"/>
    <limit effort="10.073439999999998" velocity="38.839999999999996"/>
  </joint>
  <transmission name="link1_link2_trans">
    <type>transmission_interface/SimpleTransmission</type>
    <actuator name="motor2">
      <mechanicalReduction>10</mechanicalReduction>
    </actuator>
    <joint name="link1_to_link2">
      <hardwareInterface>hardware_interface/EffortJointInterface</hardwareInterface>
    </joint>
  </transmission>
  <!-- Link 3  -->
  <link name="link3">
    <visual>
      <geometry>
        <mesh filename="package://leg_description/meshes/link3.STL" scale=".001 .001 .001"/>
      </geometry>
      <origin rpy="0 0 0" xyz="0 0 0"/>
      <material name="grey"/>
    </visual>
    <collision name="link3_leg">
      <geometry>
        <cylinder length="0.223" radius="0.0205"/>
      </geometry>
      <origin rpy="0 1.5707963267948966 0" xyz="0.1115 0 0"/>
    </collision>
    <collision name="link3_knee">
      <geometry>
        <cylinder length="0.041" radius="0.025"/>
      </geometry>
      <origin rpy="0 0 0" xyz="0 0 0"/>
    </collision>
    <collision name="link3_foot">
      <geometry>
        <sphere radius="0.0225"/>
      </geometry>
      <origin rpy="0 0 0" xyz="0.223 0 0"/>
    </collision>
    <inertial>
      <mass value="0.36814"/>
      <inertia ixx="8.8159e-05" ixy="0" ixz="0" iyy="0.003793802" iyz="0" izz="0.003804351"/>
      <origin rpy="0 0 0" xyz="0.10653 0 0"/>
    </inertial>
  </link>
  <joint name="link2_to_link3" type="revolute">
    <parent link="link2"/>
    <child link="link3"/>
    <axis rpy="0 0 0" xyz="0 0 1"/>
    <origin rpy="0 0 0" xyz="0.2531 0  0"/>
    <limit effort="10.073439999999998" lower="-2.229" upper="2.229" velocity="38.839999999999996"/>
  </joint>
  <transmission name="link2_link3_trans">
    <type>transmission_interface/SimpleTransmission</type>
    <actuator name="motor3">
      <mechanicalReduction>10</mechanicalReduction>
    </actuator>
    <joint name="link2_to_link3">
      <hardwareInterface>hardware_interface/EffortJointInterface</hardwareInterface>
    </joint>
  </transmission>
  <!-- Gazebo references -->
  <gazebo reference="base_link">
    <material> Gazebo/Blue </material>
    <kinematic> true </kinematic>
  </gazebo>
  <!-- Gazebo -->
  <gazebo>
    <plugin filename="libgazebo_ros_control.so" name="gazebo_ros_control">
      <robotNamespace>/leg</robotNamespace>
    </plugin>
  </gazebo>
</robot>
